2024-06-14 04:59:38,690 ERROR scheduler Exception in Enqueue Events for Site shivam.nbnext.in
Traceback (most recent call last):
  File "/home/ubuntu/thenb-bench/apps/frappe/frappe/utils/scheduler.py", line 75, in enqueue_events_for_site
    if is_scheduler_inactive():
  File "/home/ubuntu/thenb-bench/apps/frappe/frappe/utils/scheduler.py", line 117, in is_scheduler_inactive
    if is_scheduler_disabled(verbose=verbose):
  File "/home/ubuntu/thenb-bench/apps/frappe/frappe/utils/scheduler.py", line 130, in is_scheduler_disabled
    frappe.db.get_single_value("System Settings", "enable_scheduler")
  File "/home/ubuntu/thenb-bench/apps/frappe/frappe/database/database.py", line 841, in get_single_value
    ).run()
  File "/home/ubuntu/thenb-bench/apps/frappe/frappe/query_builder/utils.py", line 87, in execute_query
    result = frappe.db.sql(query, params, *args, **kwargs)  # nosemgrep
  File "/home/ubuntu/thenb-bench/apps/frappe/frappe/database/database.py", line 211, in sql
    self.connect()
  File "/home/ubuntu/thenb-bench/apps/frappe/frappe/database/database.py", line 117, in connect
    self._conn: "MariadbConnection" | "PostgresConnection" = self.get_connection()
  File "/home/ubuntu/thenb-bench/apps/frappe/frappe/database/mariadb/database.py", line 107, in get_connection
    conn = self._get_connection()
  File "/home/ubuntu/thenb-bench/apps/frappe/frappe/database/mariadb/database.py", line 113, in _get_connection
    return self.create_connection()
  File "/home/ubuntu/thenb-bench/apps/frappe/frappe/database/mariadb/database.py", line 116, in create_connection
    return pymysql.connect(**self.get_connection_settings())
  File "/home/ubuntu/thenb-bench/env/lib/python3.10/site-packages/pymysql/connections.py", line 361, in __init__
    self.connect()
  File "/home/ubuntu/thenb-bench/env/lib/python3.10/site-packages/pymysql/connections.py", line 669, in connect
    self._request_authentication()
  File "/home/ubuntu/thenb-bench/env/lib/python3.10/site-packages/pymysql/connections.py", line 957, in _request_authentication
    auth_packet = self._read_packet()
  File "/home/ubuntu/thenb-bench/env/lib/python3.10/site-packages/pymysql/connections.py", line 775, in _read_packet
    packet.raise_for_error()
  File "/home/ubuntu/thenb-bench/env/lib/python3.10/site-packages/pymysql/protocol.py", line 219, in raise_for_error
    err.raise_mysql_exception(self._data)
  File "/home/ubuntu/thenb-bench/env/lib/python3.10/site-packages/pymysql/err.py", line 150, in raise_mysql_exception
    raise errorclass(errno, errval)
pymysql.err.OperationalError: (1045, "Access denied for user 'ubuntu'@'localhost' (using password: NO)")
2024-06-14 05:00:38,798 ERROR scheduler Exception in Enqueue Events for Site shivam.nbnext.in
Traceback (most recent call last):
  File "/home/ubuntu/thenb-bench/apps/frappe/frappe/utils/scheduler.py", line 75, in enqueue_events_for_site
    if is_scheduler_inactive():
  File "/home/ubuntu/thenb-bench/apps/frappe/frappe/utils/scheduler.py", line 117, in is_scheduler_inactive
    if is_scheduler_disabled(verbose=verbose):
  File "/home/ubuntu/thenb-bench/apps/frappe/frappe/utils/scheduler.py", line 130, in is_scheduler_disabled
    frappe.db.get_single_value("System Settings", "enable_scheduler")
  File "/home/ubuntu/thenb-bench/apps/frappe/frappe/database/database.py", line 841, in get_single_value
    ).run()
  File "/home/ubuntu/thenb-bench/apps/frappe/frappe/query_builder/utils.py", line 87, in execute_query
    result = frappe.db.sql(query, params, *args, **kwargs)  # nosemgrep
  File "/home/ubuntu/thenb-bench/apps/frappe/frappe/database/database.py", line 211, in sql
    self.connect()
  File "/home/ubuntu/thenb-bench/apps/frappe/frappe/database/database.py", line 117, in connect
    self._conn: "MariadbConnection" | "PostgresConnection" = self.get_connection()
  File "/home/ubuntu/thenb-bench/apps/frappe/frappe/database/mariadb/database.py", line 107, in get_connection
    conn = self._get_connection()
  File "/home/ubuntu/thenb-bench/apps/frappe/frappe/database/mariadb/database.py", line 113, in _get_connection
    return self.create_connection()
  File "/home/ubuntu/thenb-bench/apps/frappe/frappe/database/mariadb/database.py", line 116, in create_connection
    return pymysql.connect(**self.get_connection_settings())
  File "/home/ubuntu/thenb-bench/env/lib/python3.10/site-packages/pymysql/connections.py", line 361, in __init__
    self.connect()
  File "/home/ubuntu/thenb-bench/env/lib/python3.10/site-packages/pymysql/connections.py", line 669, in connect
    self._request_authentication()
  File "/home/ubuntu/thenb-bench/env/lib/python3.10/site-packages/pymysql/connections.py", line 957, in _request_authentication
    auth_packet = self._read_packet()
  File "/home/ubuntu/thenb-bench/env/lib/python3.10/site-packages/pymysql/connections.py", line 775, in _read_packet
    packet.raise_for_error()
  File "/home/ubuntu/thenb-bench/env/lib/python3.10/site-packages/pymysql/protocol.py", line 219, in raise_for_error
    err.raise_mysql_exception(self._data)
  File "/home/ubuntu/thenb-bench/env/lib/python3.10/site-packages/pymysql/err.py", line 150, in raise_mysql_exception
    raise errorclass(errno, errval)
pymysql.err.OperationalError: (1045, "Access denied for user 'ubuntu'@'localhost' (using password: NO)")
2024-06-14 05:01:38,904 ERROR scheduler Exception in Enqueue Events for Site shivam.nbnext.in
Traceback (most recent call last):
  File "/home/ubuntu/thenb-bench/apps/frappe/frappe/utils/scheduler.py", line 75, in enqueue_events_for_site
    if is_scheduler_inactive():
  File "/home/ubuntu/thenb-bench/apps/frappe/frappe/utils/scheduler.py", line 117, in is_scheduler_inactive
    if is_scheduler_disabled(verbose=verbose):
  File "/home/ubuntu/thenb-bench/apps/frappe/frappe/utils/scheduler.py", line 130, in is_scheduler_disabled
    frappe.db.get_single_value("System Settings", "enable_scheduler")
  File "/home/ubuntu/thenb-bench/apps/frappe/frappe/database/database.py", line 841, in get_single_value
    ).run()
  File "/home/ubuntu/thenb-bench/apps/frappe/frappe/query_builder/utils.py", line 87, in execute_query
    result = frappe.db.sql(query, params, *args, **kwargs)  # nosemgrep
  File "/home/ubuntu/thenb-bench/apps/frappe/frappe/database/database.py", line 211, in sql
    self.connect()
  File "/home/ubuntu/thenb-bench/apps/frappe/frappe/database/database.py", line 117, in connect
    self._conn: "MariadbConnection" | "PostgresConnection" = self.get_connection()
  File "/home/ubuntu/thenb-bench/apps/frappe/frappe/database/mariadb/database.py", line 107, in get_connection
    conn = self._get_connection()
  File "/home/ubuntu/thenb-bench/apps/frappe/frappe/database/mariadb/database.py", line 113, in _get_connection
    return self.create_connection()
  File "/home/ubuntu/thenb-bench/apps/frappe/frappe/database/mariadb/database.py", line 116, in create_connection
    return pymysql.connect(**self.get_connection_settings())
  File "/home/ubuntu/thenb-bench/env/lib/python3.10/site-packages/pymysql/connections.py", line 361, in __init__
    self.connect()
  File "/home/ubuntu/thenb-bench/env/lib/python3.10/site-packages/pymysql/connections.py", line 669, in connect
    self._request_authentication()
  File "/home/ubuntu/thenb-bench/env/lib/python3.10/site-packages/pymysql/connections.py", line 957, in _request_authentication
    auth_packet = self._read_packet()
  File "/home/ubuntu/thenb-bench/env/lib/python3.10/site-packages/pymysql/connections.py", line 775, in _read_packet
    packet.raise_for_error()
  File "/home/ubuntu/thenb-bench/env/lib/python3.10/site-packages/pymysql/protocol.py", line 219, in raise_for_error
    err.raise_mysql_exception(self._data)
  File "/home/ubuntu/thenb-bench/env/lib/python3.10/site-packages/pymysql/err.py", line 150, in raise_mysql_exception
    raise errorclass(errno, errval)
pymysql.err.OperationalError: (1045, "Access denied for user 'ubuntu'@'localhost' (using password: NO)")
2024-06-15 04:44:04,701 ERROR scheduler Exception in Enqueue Events for Site shivam.nbnext.in
Traceback (most recent call last):
  File "/home/ubuntu/thenb-bench/env/lib/python3.10/site-packages/pymysql/connections.py", line 649, in connect
    sock = socket.create_connection(
  File "/usr/lib/python3.10/socket.py", line 845, in create_connection
    raise err
  File "/usr/lib/python3.10/socket.py", line 833, in create_connection
    sock.connect(sa)
ConnectionRefusedError: [Errno 111] Connection refused

During handling of the above exception, another exception occurred:

Traceback (most recent call last):
  File "/home/ubuntu/thenb-bench/apps/frappe/frappe/utils/scheduler.py", line 75, in enqueue_events_for_site
    if is_scheduler_inactive():
  File "/home/ubuntu/thenb-bench/apps/frappe/frappe/utils/scheduler.py", line 117, in is_scheduler_inactive
    if is_scheduler_disabled(verbose=verbose):
  File "/home/ubuntu/thenb-bench/apps/frappe/frappe/utils/scheduler.py", line 130, in is_scheduler_disabled
    frappe.db.get_single_value("System Settings", "enable_scheduler")
  File "/home/ubuntu/thenb-bench/apps/frappe/frappe/database/database.py", line 841, in get_single_value
    ).run()
  File "/home/ubuntu/thenb-bench/apps/frappe/frappe/query_builder/utils.py", line 87, in execute_query
    result = frappe.db.sql(query, params, *args, **kwargs)  # nosemgrep
  File "/home/ubuntu/thenb-bench/apps/frappe/frappe/database/database.py", line 211, in sql
    self.connect()
  File "/home/ubuntu/thenb-bench/apps/frappe/frappe/database/database.py", line 117, in connect
    self._conn: "MariadbConnection" | "PostgresConnection" = self.get_connection()
  File "/home/ubuntu/thenb-bench/apps/frappe/frappe/database/mariadb/database.py", line 107, in get_connection
    conn = self._get_connection()
  File "/home/ubuntu/thenb-bench/apps/frappe/frappe/database/mariadb/database.py", line 113, in _get_connection
    return self.create_connection()
  File "/home/ubuntu/thenb-bench/apps/frappe/frappe/database/mariadb/database.py", line 116, in create_connection
    return pymysql.connect(**self.get_connection_settings())
  File "/home/ubuntu/thenb-bench/env/lib/python3.10/site-packages/pymysql/connections.py", line 361, in __init__
    self.connect()
  File "/home/ubuntu/thenb-bench/env/lib/python3.10/site-packages/pymysql/connections.py", line 716, in connect
    raise exc
pymysql.err.OperationalError: (2003, "Can't connect to MySQL server on '127.0.0.1' ([Errno 111] Connection refused)")
2024-06-18 04:02:16,929 ERROR scheduler Skipped queueing frappe.social.doctype.energy_point_log.energy_point_log.send_weekly_summary because it was found in queue for shivam.nbnext.in
2024-06-18 04:02:16,940 ERROR scheduler Skipped queueing frappe.utils.change_log.check_for_update because it was found in queue for shivam.nbnext.in
2024-06-18 04:02:16,947 ERROR scheduler Skipped queueing frappe.desk.form.document_follow.send_weekly_updates because it was found in queue for shivam.nbnext.in
2024-06-18 04:02:16,954 ERROR scheduler Skipped queueing frappe.integrations.doctype.s3_backup_settings.s3_backup_settings.take_backups_weekly because it was found in queue for shivam.nbnext.in
2024-06-18 04:02:16,961 ERROR scheduler Skipped queueing frappe.integrations.doctype.dropbox_settings.dropbox_settings.take_backups_weekly because it was found in queue for shivam.nbnext.in
2024-06-18 04:02:16,967 ERROR scheduler Skipped queueing frappe.integrations.doctype.google_drive.google_drive.daily_backup because it was found in queue for shivam.nbnext.in
2024-06-18 04:02:16,974 ERROR scheduler Skipped queueing frappe.email.doctype.auto_email_report.auto_email_report.send_daily because it was found in queue for shivam.nbnext.in
2024-06-18 04:02:16,981 ERROR scheduler Skipped queueing frappe.integrations.doctype.s3_backup_settings.s3_backup_settings.take_backups_daily because it was found in queue for shivam.nbnext.in
2024-06-18 04:02:16,989 ERROR scheduler Skipped queueing frappe.integrations.doctype.dropbox_settings.dropbox_settings.take_backups_daily because it was found in queue for shivam.nbnext.in
